2021-01-09 15:33:59,499 - F:/autotest/scripts1/utils/log.py[line:87] - ERROR: error333
